[2023-10-18T16:25:34.020+0000] {taskinstance.py:1157} INFO - Dependencies all met for dep_context=non-requeueable deps ti=<TaskInstance: booking_ingestion.load_data manual__2023-10-18T16:25:26.516181+00:00 [queued]>
[2023-10-18T16:25:34.039+0000] {taskinstance.py:1157} INFO - Dependencies all met for dep_context=requeueable deps ti=<TaskInstance: booking_ingestion.load_data manual__2023-10-18T16:25:26.516181+00:00 [queued]>
[2023-10-18T16:25:34.040+0000] {taskinstance.py:1359} INFO - Starting attempt 1 of 1
[2023-10-18T16:25:34.087+0000] {taskinstance.py:1380} INFO - Executing <Task(PythonOperator): load_data> on 2023-10-18 16:25:26.516181+00:00
[2023-10-18T16:25:34.090+0000] {standard_task_runner.py:57} INFO - Started process 251 to run task
[2023-10-18T16:25:34.092+0000] {standard_task_runner.py:84} INFO - Running: ['airflow', 'tasks', 'run', 'booking_ingestion', 'load_data', 'manual__2023-10-18T16:25:26.516181+00:00', '--job-id', '14', '--raw', '--subdir', 'DAGS_FOLDER/booking_ingestion.py', '--cfg-path', '/tmp/tmpsdmb89z8']
[2023-10-18T16:25:34.093+0000] {standard_task_runner.py:85} INFO - Job 14: Subtask load_data
[2023-10-18T16:25:34.166+0000] {task_command.py:415} INFO - Running <TaskInstance: booking_ingestion.load_data manual__2023-10-18T16:25:26.516181+00:00 [running]> on host 55027e8c738b
[2023-10-18T16:25:34.468+0000] {taskinstance.py:1660} INFO - Exporting env vars: AIRFLOW_CTX_DAG_OWNER='airflow' AIRFLOW_CTX_DAG_ID='booking_ingestion' AIRFLOW_CTX_TASK_ID='load_data' AIRFLOW_CTX_EXECUTION_DATE='2023-10-18T16:25:26.516181+00:00' AIRFLOW_CTX_TRY_NUMBER='1' AIRFLOW_CTX_DAG_RUN_ID='manual__2023-10-18T16:25:26.516181+00:00'
[2023-10-18T16:25:34.470+0000] {taskinstance.py:1935} ERROR - Task failed with exception
Traceback (most recent call last):
  File "/home/airflow/.local/lib/python3.8/site-packages/airflow/operators/python.py", line 192, in execute
    return_value = self.execute_callable()
  File "/home/airflow/.local/lib/python3.8/site-packages/airflow/operators/python.py", line 209, in execute_callable
    return self.python_callable(*self.op_args, **self.op_kwargs)
  File "/opt/airflow/dags/booking_ingestion.py", line 58, in load_data
    conn = sqlite3.connect("/usr/local/airflow/db/datascience.db")
sqlite3.OperationalError: unable to open database file
[2023-10-18T16:25:34.485+0000] {taskinstance.py:1398} INFO - Marking task as FAILED. dag_id=booking_ingestion, task_id=load_data, execution_date=20231018T162526, start_date=20231018T162534, end_date=20231018T162534
[2023-10-18T16:25:34.513+0000] {standard_task_runner.py:104} ERROR - Failed to execute job 14 for task load_data (unable to open database file; 251)
[2023-10-18T16:25:34.546+0000] {local_task_job_runner.py:228} INFO - Task exited with return code 1
[2023-10-18T16:25:34.566+0000] {taskinstance.py:2776} INFO - 0 downstream tasks scheduled from follow-on schedule check
