[2023-10-18T16:24:24.151+0000] {taskinstance.py:1157} INFO - Dependencies all met for dep_context=non-requeueable deps ti=<TaskInstance: booking_ingestion.load_data manual__2023-10-18T16:24:16.147062+00:00 [queued]>
[2023-10-18T16:24:24.169+0000] {taskinstance.py:1157} INFO - Dependencies all met for dep_context=requeueable deps ti=<TaskInstance: booking_ingestion.load_data manual__2023-10-18T16:24:16.147062+00:00 [queued]>
[2023-10-18T16:24:24.170+0000] {taskinstance.py:1359} INFO - Starting attempt 1 of 1
[2023-10-18T16:24:24.212+0000] {taskinstance.py:1380} INFO - Executing <Task(PythonOperator): load_data> on 2023-10-18 16:24:16.147062+00:00
[2023-10-18T16:24:24.216+0000] {standard_task_runner.py:57} INFO - Started process 223 to run task
[2023-10-18T16:24:24.218+0000] {standard_task_runner.py:84} INFO - Running: ['airflow', 'tasks', 'run', 'booking_ingestion', 'load_data', 'manual__2023-10-18T16:24:16.147062+00:00', '--job-id', '12', '--raw', '--subdir', 'DAGS_FOLDER/booking_ingestion.py', '--cfg-path', '/tmp/tmp_a5ib0tw']
[2023-10-18T16:24:24.219+0000] {standard_task_runner.py:85} INFO - Job 12: Subtask load_data
[2023-10-18T16:24:24.298+0000] {task_command.py:415} INFO - Running <TaskInstance: booking_ingestion.load_data manual__2023-10-18T16:24:16.147062+00:00 [running]> on host 55027e8c738b
[2023-10-18T16:24:24.603+0000] {taskinstance.py:1660} INFO - Exporting env vars: AIRFLOW_CTX_DAG_OWNER='airflow' AIRFLOW_CTX_DAG_ID='booking_ingestion' AIRFLOW_CTX_TASK_ID='load_data' AIRFLOW_CTX_EXECUTION_DATE='2023-10-18T16:24:16.147062+00:00' AIRFLOW_CTX_TRY_NUMBER='1' AIRFLOW_CTX_DAG_RUN_ID='manual__2023-10-18T16:24:16.147062+00:00'
[2023-10-18T16:24:24.605+0000] {taskinstance.py:1935} ERROR - Task failed with exception
Traceback (most recent call last):
  File "/home/airflow/.local/lib/python3.8/site-packages/airflow/operators/python.py", line 192, in execute
    return_value = self.execute_callable()
  File "/home/airflow/.local/lib/python3.8/site-packages/airflow/operators/python.py", line 209, in execute_callable
    return self.python_callable(*self.op_args, **self.op_kwargs)
  File "/opt/airflow/dags/booking_ingestion.py", line 58, in load_data
    conn = sqlite3.connect("/usr/local/airflow/db/datascience.db")
sqlite3.OperationalError: unable to open database file
[2023-10-18T16:24:24.621+0000] {taskinstance.py:1398} INFO - Marking task as FAILED. dag_id=booking_ingestion, task_id=load_data, execution_date=20231018T162416, start_date=20231018T162424, end_date=20231018T162424
[2023-10-18T16:24:24.662+0000] {standard_task_runner.py:104} ERROR - Failed to execute job 12 for task load_data (unable to open database file; 223)
[2023-10-18T16:24:24.672+0000] {local_task_job_runner.py:228} INFO - Task exited with return code 1
[2023-10-18T16:24:24.696+0000] {taskinstance.py:2776} INFO - 0 downstream tasks scheduled from follow-on schedule check
